Workbook

Sheet README
A1: Human Validation — Analysis Workbook
A2: This workbook traces the two coders' raw Taguette ratings through to Tables 5-7 of the manuscript.
A3: All grey-tabbed computation sheets use LIVE FORMULAS; edit the blue input cells on 'Raw ratings' and every result recomputes.
A5: Design: 30 no-RAKE baseline topics (15 LDA + 15 NMF), each rated by a Main coder (C1) and a Secondary coder (C2)
A6: on four criteria — Coherence, Domain, Label, Fidelity — giving 30×2×4 = 240 judgments. Topics were blinded to model identity.
A8: Sheets:
A9: • Raw ratings — the coders' tags per topic (BLUE = raw input), plus the topic key and ordinal encodings (formulas).
A10: • A_Reliability(kappa) — inter-coder contingency tables → percent agreement and Cohen's kappa (Panel A/Table 5).
A11: • B_NMF_vs_LDA(MW) — ordinal ratings pooled by model, ranked → Mann–Whitney U and p, and group means (Panel B/Table 6).
A12: • C_Domain_concordance — each coder's domain vs the model → confusion matrices, accuracy, macro-F1 (Panel C/Table 7).
A13: • Table 5 — the three panels as they appear in the paper, pulled from the sheets above.
A15: Encodings (ordinal 1–3): Coherence Low/Medium/High=1/2/3; Label Poor/Acceptable/Good=1/2/3; Fidelity Artifact/Mixed/Authentic=1/2/3.
... A18: continuity correction (one-sided, NMF > LDA); verified to match scipy.stats.mannwhitneyu.

Sheet Raw ratings
A1: TopicID | B1: Model | C1: OrigTopic | D1: ModelDomainRaw | E1: ModelDomain | F1: C1_Coherence | G1: C1_Domain | H1: C1_Label | I1: C1_Fidelity | J1: C2_Coherence | K1: C2_Domain | L1: C2_Label | M1: C2_Fidelity | N1: C1_Coh# | O1: C1_Lab# | P1: C1_Fid# | Q1: C2_Coh# | R1: C2_Lab# | S1: C2_Fid# | T1: C1_DomCorrect | U1: C2_DomCorrect | V1: C1C2_DomAgree
A2: T01 | B2: NMF | C2: 4 | D2: D | E2: =IF(D2="?","Inductive",D2) -> D | F2: Medium | G2: A | H2: Good | I2: Mixed | J2: High | K2: A | L2: Acceptable | M2: Authentic | N2: =IF(F2="High",3,IF(F2="Medium",2,1)) -> 2 | O2: =IF(H2="Good",3,IF(H2="Acceptable",2,1)) -> 3 | P2: =IF(I2="Authentic",3,IF(I2="Mixed",2,1)) -> 2 | Q2: =IF(J2="High",3,IF(J2="Medium",2,1)) -> 3 | R2: =IF(L2="Good",3,IF(L2="Acceptable",2,1)) -> 2 | S2: =IF(M2="Authentic",3,IF(M2="Mixed",2,1)) -> 3 | T2: =IF(E2=G2,1,0) -> 0 | U2: =IF(E2=K2,1,0) -> 0 | V2: =IF(G2=K2,1,0) -> 1
A3: T02 | B3: LDA | C3: 14 | D3: ? | E3: =IF(D3="?","Inductive",D3) -> Inductive | F3: Low | G3: Inductive | H3: Poor | I3: Artifact | J3: Low | K3: Inductive | L3: Poor | M3: Artifact | N3: =IF(F3="High",3,IF(F3="Medium",2,1)) -> 1 | O3: =IF(H3="Good",3,IF(H3="Acceptable",2,1)) -> 1 | P3: =IF(I3="Authentic",3,IF(I3="Mixed",2,1)) -> 1 | Q3: =IF(J3="High",3,IF(J3="Medium",2,1)) -> 1 | R3: =IF(L3="Good",3,IF(L3="Acceptable",2,1)) -> 1 | S3: =IF(M3="Authentic",3,IF(M3="Mixed",2,1)) -> 1 | T3: =IF(E3=G3,1,0) -> 1 | U3: =IF(E3=K3,1,0) -> 1 | V3: =IF(G3=K3,1,0) -> 1
A4: T03 | B4: LDA | C4: 10 | D4: B | E4: =IF(D4="?","Inductive",D4) -> B | F4: Medium | G4: Inductive | H4: Acceptable | I4: Mixed | J4: Medium | K4: D | L4: Poor | M4: Mixed | N4: =IF(F4="High",3,IF(F4="Medium",2,1)) -> 2 | O4: =IF(H4="Good",3,IF(H4="Acceptable",2,1)) -> 2 | P4: =IF(I4="Authentic",3,IF(I4="Mixed",2,1)) -> 2 | Q4: =IF(J4="High",3,IF(J4="Medium",2,1)) -> 2 | R4: =IF(L4="Good",3,IF(L4="Acceptable",2,1)) -> 1 | S4: =IF(M4="Authentic",3,IF(M4="Mixed",2,1)) -> 2 | T4: =IF(E4=G4,1,0) -> 0 | U4: =IF(E4=K4,1,0) -> 0 | V4: =IF(G4=K4,1,0) -> 0
A5: T04 | B5: NMF | C5: 11 | D5: B | E5: =IF(D5="?","Inductive",D5) -> B | F5: High | G5: B | H5: Good | I5: Authentic | J5: High | K5: B | L5: Good | M5: Authentic | N5: =IF(F5="High",3,IF(F5="Medium",2,1)) -> 3 | O5: =IF(H5="Good",3,IF(H5="Acceptable",2,1)) -> 3 | P5: =IF(I5="Authentic",3,IF(I5="Mixed",2,1)) -> 3 | Q5: =IF(J5="High",3,IF(J5="Medium",2,1)) -> 3 | R5: =IF(L5="Good",3,IF(L5="Acceptable",2,1)) -> 3 | S5: =IF(M5="Authentic",3,IF(M5="Mixed",2,1)) -> 3 | T5: =IF(E5=G5,1,0) -> 1 | U5: =IF(E5=K5,1,0) -> 1 | V5: =IF(G5=K5,1,0) -> 1
A6: T05 | B6: NMF | C6: 7 | D6: B | E6: =IF(D6="?","Inductive",D6) -> B | F6: High | G6: B | H6: Good | I6: Authentic | J6: High | K6: B | L6: Acceptable | M6: Authentic | N6: =IF(F6="High",3,IF(F6="Medium",2,1)) -> 3 | O6: =IF(H6="Good",3,IF(H6="Acceptable",2,1)) -> 3 | P6: =IF(I6="Authentic",3,IF(I6="Mixed",2,1)) -> 3 | Q6: =IF(J6="High",3,IF(J6="Medium",2,1)) -> 3 | R6: =IF(L6="Good",3,IF(L6="Acceptable",2,1)) -> 2 | S6: =IF(M6="Authentic",3,IF(M6="Mixed",2,1)) -> 3 | T6: =IF(E6=G6,1,0) -> 1 | U6: =IF(E6=K6,1,0) -> 1 | V6: =IF(G6=K6,1,0) -> 1
A7: T06 | B7: LDA | C7: 6 | D7: ? | E7: =IF(D7="?","Inductive",D7) -> Inductive | F7: Medium | G7: B | H7: Good | I7: Mixed | J7: Low | K7: Inductive | L7: Poor | M7: Artifact | N7: =IF(F7="High",3,IF(F7="Medium",2,1)) -> 2 | O7: =IF(H7="Good",3,IF(H7="Acceptable",2,1)) -> 3 | P7: =IF(I7="Authentic",3,IF(I7="Mixed",2,1)) -> 2 | Q7: =IF(J7="High",3,IF(J7="Medium",2,1)) -> 1 | R7: =IF(L7="Good",3,IF(L7="Acceptable",2,1)) -> 1 | S7: =IF(M7="Authentic",3,IF(M7="Mixed",2,1)) -> 1 | T7: =IF(E7=G7,1,0) -> 0 | U7: =IF(E7=K7,1,0) -> 1 | V7: =IF(G7=K7,1,0) -> 0
A8: T07 | B8: LDA | C8: 5 | D8: B | E8: =IF(D8="?","Inductive",D8) -> B | F8: Medium | G8: B | H8: Acceptable | I8: Mixed | J8: Medium | K8: B | L8: Poor | M8: Authentic | N8: =IF(F8="High",3,IF(F8="Medium",2,1)) -> 2 | O8: =IF(H8="Good",3,IF(H8="Acceptable",2,1)) -> 2 | P8: =IF(I8="Authentic",3,IF(I8="Mixed",2,1)) -> 2 | Q8: =IF(J8="High",3,IF(J8="Medium",2,1)) -> 2 | R8: =IF(L8="Good",3,IF(L8="Acceptable",2,1)) -> 1 | S8: =IF(M8="Authentic",3,IF(M8="Mixed",2,1)) -> 3 | T8: =IF(E8=G8,1,0) -> 1 | U8: =IF(E8=K8,1,0) -> 1 | V8: =IF(G8=K8,1,0) -> 1
A9: T08 | B9: LDA | C9: 12 | D9: B | E9: =IF(D9="?","Inductive",D9) -> B | F9: Medium | G9: B | H9: Acceptable | I9: Authentic | J9: High | K9: B | L9: Acceptable | M9: Authentic | N9: =IF(F9="High",3,IF(F9="Medium",2,1)) -> 2 | O9: =IF(H9="Good",3,IF(H9="Acceptable",2,1)) -> 2 | P9: =IF(I9="Authentic",3,IF(I9="Mixed",2,1)) -> 3 | Q9: =IF(J9="High",3,IF(J9="Medium",2,1)) -> 3 | R9: =IF(L9="Good",3,IF(L9="Acceptable",2,1)) -> 2 | S9: =IF(M9="Authentic",3,IF(M9="Mixed",2,1)) -> 3 | T9: =IF(E9=G9,1,0) -> 1 | U9: =IF(E9=K9,1,0) -> 1 | V9: =IF(G9=K9,1,0) -> 1
A10: T09 | B10: LDA | C10: 11 | D10: ? | E10: =IF(D10="?","Inductive",D10) -> Inductive | F10: Low | G10: Inductive | H10: Poor | I10: Mixed | J10: Medium | K10: D | L10: Poor | M10: Authentic | N10: =IF(F10="High",3,IF(F10="Medium",2,1)) -> 1 | O10: =IF(H10="Good",3,IF(H10="Acceptable",2,1)) -> 1 | P10: =IF(I10="Authentic",3,IF(I10="Mixed",2,1)) -> 2 | Q10: =IF(J10="High",3,IF(J10="Medium",2,1)) -> 2 | R10: =IF(L10="Good",3,IF(L10="Acceptable",2,1)) -> 1 | S10: =IF(M10="Authentic",3,IF(M10="Mixed",2,1)) -> 3 | T10: =IF(E10=G10,1,0) -> 1 | U10: =IF(E10=K10,1,0) -> 0 | V10: =IF(G10=K10,1,0) -> 0
A11: T10 | B11: NMF | C11: 0 | D11: B | E11: =IF(D11="?","Inductive",D11) -> B | F11: High | G11: B | H11: Good | I11: Authentic | J11: Medium | K11: B | L11: Acceptable | M11: Authentic | N11: =IF(F11="High",3,IF(F11="Medium",2,1)) -> 3 | O11: =IF(H11="Good",3,IF(H11="Acceptable",2,1)) -> 3 | P11: =IF(I11="Authentic",3,IF(I11="Mixed",2,1)) -> 3 | Q11: =IF(J11="High",3,IF(J11="Medium",2,1)) -> 2 | R11: =IF(L11="Good",3,IF(L11="Acceptable",2,1)) -> 2 | S11: =IF(M11="Authentic",3,IF(M11="Mixed",2,1)) -> 3 | T11: =IF(E11=G11,1,0) -> 1 | U11: =IF(E11=K11,1,0) -> 1 | V11: =IF(G11=K11,1,0) -> 1
A12: T11 | B12: LDA | C12: 9 | D12: D | E12: =IF(D12="?","Inductive",D12) -> D | F12: Low | G12: Inductive | H12: Poor | I12: Artifact | J12: Medium | K12: D | L12: Poor | M12: Mixed | N12: =IF(F12="High",3,IF(F12="Medium",2,1)) -> 1 | O12: =IF(H12="Good",3,IF(H12="Acceptable",2,1)) -> 1 | P12: =IF(I12="Authentic",3,IF(I12="Mixed",2,1)) -> 1 | Q12: =IF(J12="High",3,IF(J12="Medium",2,1)) -> 2 | R12: =IF(L12="Good",3,IF(L12="Acceptable",2,1)) -> 1 | S12: =IF(M12="Authentic",3,IF(M12="Mixed",2,1)) -> 2 | T12: =IF(E12=G12,1,0) -> 0 | U12: =IF(E12=K12,1,0) -> 1 | V12: =IF(G12=K12,1,0) -> 0
A13: T12 | B13: NMF | C13: 10 | D13: B | E13: =IF(D13="?","Inductive",D13) -> B | F13: High | G13: B | H13: Good | I13: Authentic | J13: High | K13: B | L13: Acceptable | M13: Authentic | N13: =IF(F13="High",3,IF(F13="Medium",2,1)) -> 3 | O13: =IF(H13="Good",3,IF(H13="Acceptable",2,1)) -> 3 | P13: =IF(I13="Authentic",3,IF(I13="Mixed",2,1)) -> 3 | Q13: =IF(J13="High",3,IF(J13="Medium",2,1)) -> 3 | R13: =IF(L13="Good",3,IF(L13="Acceptable",2,1)) -> 2 | S13: =IF(M13="Authentic",3,IF(M13="Mixed",2,1)) -> 3 | T13: =IF(E13=G13,1,0) -> 1 | U13: =IF(E13=K13,1,0) -> 1 | V13: =IF(G13=K13,1,0) -> 1
... A31: T30 | B31: NMF | C31: 5 | D31: A | E31: =IF(D31="?","Inductive",D31) -> A | F31: High | G31: B | H31: Good | I31: Authentic | J31: High | K31: B | L31: Acceptable | M31: Authentic | N31: =IF(F31="High",3,IF(F31="Medium",2,1)) -> 3 | O31: =IF(H31="Good",3,IF(H31="Acceptable",2,1)) -> 3 | P31: =IF(I31="Authentic",3,IF(I31="Mixed",2,1)) -> 3 | Q31: =IF(J31="High",3,IF(J31="Medium",2,1)) -> 3 | R31: =IF(L31="Good",3,IF(L31="Acceptable",2,1)) -> 2 | S31: =IF(M31="Authentic",3,IF(M31="Mixed",2,1)) -> 3 | T31: =IF(E31=G31,1,0) -> 0 | U31: =IF(E31=K31,1,0) -> 0 | V31: =IF(G31=K31,1,0) -> 1
A33: BLUE = raw coder input / key. Black = formula. Green = Coder 1. Red=Coder 2. Edit blue cells and all sheets recompute.

Sheet A_Reliability(kappa)
A1: Coherence — inter-coder contingency (C1 rows × C2 columns)
A2: C1 \ C2 | B2: Low | C2: Medium | D2: High | E2: Row total
A3: Low | B3: =COUNTIFS('Raw ratings'!$F$2:$F$31,"Low",'Raw ratings'!$J$2:$J$31,"Low") -> 1 | C3: =COUNTIFS('Raw ratings'!$F$2:$F$31,"Low",'Raw ratings'!$J$2:$J$31,"Medium") -> 4 | D3: =COUNTIFS('Raw ratings'!$F$2:$F$31,"Low",'Raw ratings'!$J$2:$J$31,"High") -> 1 | E3: =SUM(B3:D3) -> 6
A4: Medium | B4: =COUNTIFS('Raw ratings'!$F$2:$F$31,"Medium",'Raw ratings'!$J$2:$J$31,"Low") -> 2 | C4: =COUNTIFS('Raw ratings'!$F$2:$F$31,"Medium",'Raw ratings'!$J$2:$J$31,"Medium") -> 8 | D4: =COUNTIFS('Raw ratings'!$F$2:$F$31,"Medium",'Raw ratings'!$J$2:$J$31,"High") -> 7 | E4: =SUM(B4:D4) -> 17
A5: High | B5: =COUNTIFS('Raw ratings'!$F$2:$F$31,"High",'Raw ratings'!$J$2:$J$31,"Low") -> 0 | C5: =COUNTIFS('Raw ratings'!$F$2:$F$31,"High",'Raw ratings'!$J$2:$J$31,"Medium") -> 1 | D5: =COUNTIFS('Raw ratings'!$F$2:$F$31,"High",'Raw ratings'!$J$2:$J$31,"High") -> 6 | E5: =SUM(B5:D5) -> 7
A6: Col total | B6: =SUM(B3:B5) -> 3 | C6: =SUM(C3:C5) -> 13 | D6: =SUM(D3:D5) -> 14 | E6: =SUM(B6:D6) -> 30
A8: Observed agreement (po) | B8: =(B3+C4+D5)/E6 -> 0.5
A9: Expected agreement (pe) | B9: =(E3*B6+E4*C6+E5*D6)/(E6^2) -> 0.37444444
A10: Cohen's kappa | B10: =(B8-B9)/(1-B9) -> 0.20071048
A11: % agreement | B11: =B8 -> 0.5
A13: Domain — inter-coder contingency (C1 rows × C2 columns)
A14: C1 \ C2 | B14: A | C14: B | D14: C | E14: D | F14: Inductive | G14: Row total
A15: A | B15: =COUNTIFS('Raw ratings'!$G$2:$G$31,"A",'Raw ratings'!$K$2:$K$31,"A") -> 1 | C15: =COUNTIFS('Raw ratings'!$G$2:$G$31,"A",'Raw ratings'!$K$2:$K$31,"B") -> 0 | D15: =COUNTIFS('Raw ratings'!$G$2:$G$31,"A",'Raw ratings'!$K$2:$K$31,"C") -> 0 | E15: =COUNTIFS('Raw ratings'!$G$2:$G$31,"A",'Raw ratings'!$K$2:$K$31,"D") -> 0 | F15: =COUNTIFS('Raw ratings'!$G$2:$G$31,"A",'Raw ratings'!$K$2:$K$31,"Inductive") -> 0 | G15: =SUM(B15:F15) -> 1
A16: B | B16: =COUNTIFS('Raw ratings'!$G$2:$G$31,"B",'Raw ratings'!$K$2:$K$31,"A") -> 1 | C16: =COUNTIFS('Raw ratings'!$G$2:$G$31,"B",'Raw ratings'!$K$2:$K$31,"B") -> 14 | D16: =COUNTIFS('Raw ratings'!$G$2:$G$31,"B",'Raw ratings'!$K$2:$K$31,"C") -> 1 | E16: =COUNTIFS('Raw ratings'!$G$2:$G$31,"B",'Raw ratings'!$K$2:$K$31,"D") -> 2 | F16: =COUNTIFS('Raw ratings'!$G$2:$G$31,"B",'Raw ratings'!$K$2:$K$31,"Inductive") -> 1 | G16: =SUM(B16:F16) -> 19
A17: C | B17: =COUNTIFS('Raw ratings'!$G$2:$G$31,"C",'Raw ratings'!$K$2:$K$31,"A") -> 0 | C17: =COUNTIFS('Raw ratings'!$G$2:$G$31,"C",'Raw ratings'!$K$2:$K$31,"B") -> 0 | D17: =COUNTIFS('Raw ratings'!$G$2:$G$31,"C",'Raw ratings'!$K$2:$K$31,"C") -> 0 | E17: =COUNTIFS('Raw ratings'!$G$2:$G$31,"C",'Raw ratings'!$K$2:$K$31,"D") -> 0 | F17: =COUNTIFS('Raw ratings'!$G$2:$G$31,"C",'Raw ratings'!$K$2:$K$31,"Inductive") -> 0 | G17: =SUM(B17:F17) -> 0
A18: D | B18: =COUNTIFS('Raw ratings'!$G$2:$G$31,"D",'Raw ratings'!$K$2:$K$31,"A") -> 0 | C18: =COUNTIFS('Raw ratings'!$G$2:$G$31,"D",'Raw ratings'!$K$2:$K$31,"B") -> 0 | D18: =COUNTIFS('Raw ratings'!$G$2:$G$31,"D",'Raw ratings'!$K$2:$K$31,"C") -> 0 | E18: =COUNTIFS('Raw ratings'!$G$2:$G$31,"D",'Raw ratings'!$K$2:$K$31,"D") -> 0 | F18: =COUNTIFS('Raw ratings'!$G$2:$G$31,"D",'Raw ratings'!$K$2:$K$31,"Inductive") -> 0 | G18: =SUM(B18:F18) -> 0
A19: Inductive | B19: =COUNTIFS('Raw ratings'!$G$2:$G$31,"Inductive",'Raw ratings'!$K$2:$K$31,"A") -> 1 | C19: =COUNTIFS('Raw ratings'!$G$2:$G$31,"Inductive",'Raw ratings'!$K$2:$K$31,"B") -> 1 | D19: =COUNTIFS('Raw ratings'!$G$2:$G$31,"Inductive",'Raw ratings'!$K$2:$K$31,"C") -> 1 | E19: =COUNTIFS('Raw ratings'!$G$2:$G$31,"Inductive",'Raw ratings'!$K$2:$K$31,"D") -> 6 | F19: =COUNTIFS('Raw ratings'!$G$2:$G$31,"Inductive",'Raw ratings'!$K$2:$K$31,"Inductive") -> 1 | G19: =SUM(B19:F19) -> 10
A20: Col total | B20: =SUM(B15:B19) -> 3 | C20: =SUM(C15:C19) -> 15 | D20: =SUM(D15:D19) -> 2 | E20: =SUM(E15:E19) -> 8 | F20: =SUM(F15:F19) -> 2 | G20: =SUM(B20:F20) -> 30
A22: Observed agreement (po) | B22: =(B15+C16+D17+E18+F19)/G20 -> 0.53333333
A23: Expected agreement (pe) | B23: =(G15*B20+G16*C20+G17*D20+G18*E20+G19*F20)/(G20^2) -> 0.34222222
A24: Cohen's kappa | B24: =(B22-B23)/(1-B23) -> 0.29054054
A25: % agreement | B25: =B22 -> 0.53333333
A27: Label — inter-coder contingency (C1 rows × C2 columns)
A28: C1 \ C2 | B28: Poor | C28: Acceptable | D28: Good | E28: Row total
A29: Poor | B29: =COUNTIFS('Raw ratings'!$H$2:$H$31,"Poor",'Raw ratings'!$L$2:$L$31,"Poor") -> 10 | C29: =COUNTIFS('Raw ratings'!$H$2:$H$31,"Poor",'Raw ratings'!$L$2:$L$31,"Acceptable") -> 1 | D29: =COUNTIFS('Raw ratings'!$H$2:$H$31,"Poor",'Raw ratings'!$L$2:$L$31,"Good") -> 0 | E29: =SUM(B29:D29) -> 11
A30: Acceptable | B30: =COUNTIFS('Raw ratings'!$H$2:$H$31,"Acceptable",'Raw ratings'!$L$2:$L$31,"Poor") -> 3 | C30: =COUNTIFS('Raw ratings'!$H$2:$H$31,"Acceptable",'Raw ratings'!$L$2:$L$31,"Acceptable") -> 5 | D30: =COUNTIFS('Raw ratings'!$H$2:$H$31,"Acceptable",'Raw ratings'!$L$2:$L$31,"Good") -> 0 | E30: =SUM(B30:D30) -> 8
A31: Good | B31: =COUNTIFS('Raw ratings'!$H$2:$H$31,"Good",'Raw ratings'!$L$2:$L$31,"Poor") -> 2 | C31: =COUNTIFS('Raw ratings'!$H$2:$H$31,"Good",'Raw ratings'!$L$2:$L$31,"Acceptable") -> 6 | D31: =COUNTIFS('Raw ratings'!$H$2:$H$31,"Good",'Raw ratings'!$L$2:$L$31,"Good") -> 3 | E31: =SUM(B31:D31) -> 11
A32: Col total | B32: =SUM(B29:B31) -> 15 | C32: =SUM(C29:C31) -> 12 | D32: =SUM(D29:D31) -> 3 | E32: =SUM(B32:D32) -> 30
A34: Observed agreement (po) | B34: =(B29+C30+D31)/E32 -> 0.6
A35: Expected agreement (pe) | B35: =(E29*B32+E30*C32+E31*D32)/(E32^2) -> 0.32666667
A36: Cohen's kappa | B36: =(B34-B35)/(1-B35) -> 0.40594059
A37: % agreement | B37: =B34 -> 0.6
A39: Fidelity — inter-coder contingency (C1 rows × C2 columns)
A40: C1 \ C2 | B40: Artifact | C40: Mixed | D40: Authentic | E40: Row total
A41: Artifact | B41: =COUNTIFS('Raw ratings'!$I$2:$I$31,"Artifact",'Raw ratings'!$M$2:$M$31,"Artifact") -> 1 | C41: =COUNTIFS('Raw ratings'!$I$2:$I$31,"Artifact",'Raw ratings'!$M$2:$M$31,"Mixed") -> 1 | D41: =COUNTIFS('Raw ratings'!$I$2:$I$31,"Artifact",'Raw ratings'!$M$2:$M$31,"Authentic") -> 0 | E41: =SUM(B41:D41) -> 2
A42: Mixed | B42: =COUNTIFS('Raw ratings'!$I$2:$I$31,"Mixed",'Raw ratings'!$M$2:$M$31,"Artifact") -> 1 | C42: =COUNTIFS('Raw ratings'!$I$2:$I$31,"Mixed",'Raw ratings'!$M$2:$M$31,"Mixed") -> 4 | D42: =COUNTIFS('Raw ratings'!$I$2:$I$31,"Mixed",'Raw ratings'!$M$2:$M$31,"Authentic") -> 13 | E42: =SUM(B42:D42) -> 18
A43: Authentic | B43: =COUNTIFS('Raw ratings'!$I$2:$I$31,"Authentic",'Raw ratings'!$M$2:$M$31,"Artifact") -> 0 | C43: =COUNTIFS('Raw ratings'!$I$2:$I$31,"Authentic",'Raw ratings'!$M$2:$M$31,"Mixed") -> 0 | D43: =COUNTIFS('Raw ratings'!$I$2:$I$31,"Authentic",'Raw ratings'!$M$2:$M$31,"Authentic") -> 10 | E43: =SUM(B43:D43) -> 10
A44: Col total | B44: =SUM(B41:B43) -> 2 | C44: =SUM(C41:C43) -> 5 | D44: =SUM(D41:D43) -> 23 | E44: =SUM(B44:D44) -> 30
A46: Observed agreement (po) | B46: =(B41+C42+D43)/E44 -> 0.5
A47: Expected agreement (pe) | B47: =(E41*B44+E42*C44+E43*D44)/(E44^2) -> 0.36
...

Sheet B_NMF_vs_LDA(MW)
A1: TopicID | B1: Coder | C1: Model | D1: Coh# | E1: Lab# | F1: Fid# | G1: RankCoh | H1: RankLab | I1: RankFid | K1: Mann–Whitney U (one-sided, NMF>LDA) | L1: Coherence | M1: Label | N1: Fidelity
A2: ='Raw ratings'!A2 -> T01 | B2: C1 | C2: ='Raw ratings'!B2 -> NMF | D2: ='Raw ratings'!N2 -> 2 | E2: ='Raw ratings'!O2 -> 3 | F2: ='Raw ratings'!P2 -> 2 | G2: =COUNTIF($D$2:$D$61,"<"&D2)+(COUNTIF($D$2:$D$61,"="&D2)+1)/2 -> 24.5 | H2: =COUNTIF($E$2:$E$61,"<"&E2)+(COUNTIF($E$2:$E$61,"="&E2)+1)/2 -> 53.5 | I2: =COUNTIF($F$2:$F$61,"<"&F2)+(COUNTIF($F$2:$F$61,"="&F2)+1)/2 -> 16 | K2: n1 (LDA) | L2: =COUNTIF($C$2:$C$61,"LDA") -> 30 | M2: =COUNTIF($C$2:$C$61,"LDA") -> 30 | N2: =COUNTIF($C$2:$C$61,"LDA") -> 30
A3: ='Raw ratings'!A3 -> T02 | B3: C1 | C3: ='Raw ratings'!B3 -> LDA | D3: ='Raw ratings'!N3 -> 1 | E3: ='Raw ratings'!O3 -> 1 | F3: ='Raw ratings'!P3 -> 1 | G3: =COUNTIF($D$2:$D$61,"<"&D3)+(COUNTIF($D$2:$D$61,"="&D3)+1)/2 -> 5 | H3: =COUNTIF($E$2:$E$61,"<"&E3)+(COUNTIF($E$2:$E$61,"="&E3)+1)/2 -> 13.5 | I3: =COUNTIF($F$2:$F$61,"<"&F3)+(COUNTIF($F$2:$F$61,"="&F3)+1)/2 -> 2.5 | K3: n2 (NMF) | L3: =COUNTIF($C$2:$C$61,"NMF") -> 30 | M3: =COUNTIF($C$2:$C$61,"NMF") -> 30 | N3: =COUNTIF($C$2:$C$61,"NMF") -> 30
A4: ='Raw ratings'!A4 -> T03 | B4: C1 | C4: ='Raw ratings'!B4 -> LDA | D4: ='Raw ratings'!N4 -> 2 | E4: ='Raw ratings'!O4 -> 2 | F4: ='Raw ratings'!P4 -> 2 | G4: =COUNTIF($D$2:$D$61,"<"&D4)+(COUNTIF($D$2:$D$61,"="&D4)+1)/2 -> 24.5 | H4: =COUNTIF($E$2:$E$61,"<"&E4)+(COUNTIF($E$2:$E$61,"="&E4)+1)/2 -> 36.5 | I4: =COUNTIF($F$2:$F$61,"<"&F4)+(COUNTIF($F$2:$F$61,"="&F4)+1)/2 -> 16 | K4: n (total) | L4: =L2+L3 -> 60 | M4: =M2+M3 -> 60 | N4: =N2+N3 -> 60
A5: ='Raw ratings'!A5 -> T04 | B5: C1 | C5: ='Raw ratings'!B5 -> NMF | D5: ='Raw ratings'!N5 -> 3 | E5: ='Raw ratings'!O5 -> 3 | F5: ='Raw ratings'!P5 -> 3 | G5: =COUNTIF($D$2:$D$61,"<"&D5)+(COUNTIF($D$2:$D$61,"="&D5)+1)/2 -> 50 | H5: =COUNTIF($E$2:$E$61,"<"&E5)+(COUNTIF($E$2:$E$61,"="&E5)+1)/2 -> 53.5 | I5: =COUNTIF($F$2:$F$61,"<"&F5)+(COUNTIF($F$2:$F$61,"="&F5)+1)/2 -> 44 | K5: Rank sum NMF | L5: =SUMIF($C$2:$C$61,"NMF",$G$2:$G$61) -> 1129.5 | M5: =SUMIF($C$2:$C$61,"NMF",$H$2:$H$61) -> 1155 | N5: =SUMIF($C$2:$C$61,"NMF",$I$2:$I$61) -> 1124
A6: ='Raw ratings'!A6 -> T05 | B6: C1 | C6: ='Raw ratings'!B6 -> NMF | D6: ='Raw ratings'!N6 -> 3 | E6: ='Raw ratings'!O6 -> 3 | F6: ='Raw ratings'!P6 -> 3 | G6: =COUNTIF($D$2:$D$61,"<"&D6)+(COUNTIF($D$2:$D$61,"="&D6)+1)/2 -> 50 | H6: =COUNTIF($E$2:$E$61,"<"&E6)+(COUNTIF($E$2:$E$61,"="&E6)+1)/2 -> 53.5 | I6: =COUNTIF($F$2:$F$61,"<"&F6)+(COUNTIF($F$2:$F$61,"="&F6)+1)/2 -> 44 | K6: U (NMF) | L6: =L5-L3*(L3+1)/2 -> 664.5 | M6: =M5-M3*(M3+1)/2 -> 690 | N6: =N5-N3*(N3+1)/2 -> 659
A7: ='Raw ratings'!A7 -> T06 | B7: C1 | C7: ='Raw ratings'!B7 -> LDA | D7: ='Raw ratings'!N7 -> 2 | E7: ='Raw ratings'!O7 -> 3 | F7: ='Raw ratings'!P7 -> 2 | G7: =COUNTIF($D$2:$D$61,"<"&D7)+(COUNTIF($D$2:$D$61,"="&D7)+1)/2 -> 24.5 | H7: =COUNTIF($E$2:$E$61,"<"&E7)+(COUNTIF($E$2:$E$61,"="&E7)+1)/2 -> 53.5 | I7: =COUNTIF($F$2:$F$61,"<"&F7)+(COUNTIF($F$2:$F$61,"="&F7)+1)/2 -> 16 | K7: mean U = n1·n2/2 | L7: =L2*L3/2 -> 450 | M7: =M2*M3/2 -> 450 | N7: =N2*N3/2 -> 450
A8: ='Raw ratings'!A8 -> T07 | B8: C1 | C8: ='Raw ratings'!B8 -> LDA | D8: ='Raw ratings'!N8 -> 2 | E8: ='Raw ratings'!O8 -> 2 | F8: ='Raw ratings'!P8 -> 2 | G8: =COUNTIF($D$2:$D$61,"<"&D8)+(COUNTIF($D$2:$D$61,"="&D8)+1)/2 -> 24.5 | H8: =COUNTIF($E$2:$E$61,"<"&E8)+(COUNTIF($E$2:$E$61,"="&E8)+1)/2 -> 36.5 | I8: =COUNTIF($F$2:$F$61,"<"&F8)+(COUNTIF($F$2:$F$61,"="&F8)+1)/2 -> 16 | K8: t(=1) | L8: =COUNTIF($D$2:$D$61,1) -> 9 | M8: =COUNTIF($E$2:$E$61,1) -> 26 | N8: =COUNTIF($F$2:$F$61,1) -> 4
A9: ='Raw ratings'!A9 -> T08 | B9: C1 | C9: ='Raw ratings'!B9 -> LDA | D9: ='Raw ratings'!N9 -> 2 | E9: ='Raw ratings'!O9 -> 2 | F9: ='Raw ratings'!P9 -> 3 | G9: =COUNTIF($D$2:$D$61,"<"&D9)+(COUNTIF($D$2:$D$61,"="&D9)+1)/2 -> 24.5 | H9: =COUNTIF($E$2:$E$61,"<"&E9)+(COUNTIF($E$2:$E$61,"="&E9)+1)/2 -> 36.5 | I9: =COUNTIF($F$2:$F$61,"<"&F9)+(COUNTIF($F$2:$F$61,"="&F9)+1)/2 -> 44 | K9: t(=2) | L9: =COUNTIF($D$2:$D$61,2) -> 30 | M9: =COUNTIF($E$2:$E$61,2) -> 20 | N9: =COUNTIF($F$2:$F$61,2) -> 23
A10: ='Raw ratings'!A10 -> T09 | B10: C1 | C10: ='Raw ratings'!B10 -> LDA | D10: ='Raw ratings'!N10 -> 1 | E10: ='Raw ratings'!O10 -> 1 | F10: ='Raw ratings'!P10 -> 2 | G10: =COUNTIF($D$2:$D$61,"<"&D10)+(COUNTIF($D$2:$D$61,"="&D10)+1)/2 -> 5 | H10: =COUNTIF($E$2:$E$61,"<"&E10)+(COUNTIF($E$2:$E$61,"="&E10)+1)/2 -> 13.5 | I10: =COUNTIF($F$2:$F$61,"<"&F10)+(COUNTIF($F$2:$F$61,"="&F10)+1)/2 -> 16 | K10: t(=3) | L10: =COUNTIF($D$2:$D$61,3) -> 21 | M10: =COUNTIF($E$2:$E$61,3) -> 14 | N10: =COUNTIF($F$2:$F$61,3) -> 33
A11: ='Raw ratings'!A11 -> T10 | B11: C1 | C11: ='Raw ratings'!B11 -> NMF | D11: ='Raw ratings'!N11 -> 3 | E11: ='Raw ratings'!O11 -> 3 | F11: ='Raw ratings'!P11 -> 3 | G11: =COUNTIF($D$2:$D$61,"<"&D11)+(COUNTIF($D$2:$D$61,"="&D11)+1)/2 -> 50 | H11: =COUNTIF($E$2:$E$61,"<"&E11)+(COUNTIF($E$2:$E$61,"="&E11)+1)/2 -> 53.5 | I11: =COUNTIF($F$2:$F$61,"<"&F11)+(COUNTIF($F$2:$F$61,"="&F11)+1)/2 -> 44 | K11: T = Σ(t³−t) | L11: =(L8^3-L8)+(L9^3-L9)+(L10^3-L10) -> 36930 | M11: =(M8^3-M8)+(M9^3-M9)+(M10^3-M10) -> 28260 | N11: =(N8^3-N8)+(N9^3-N9)+(N10^3-N10) -> 48108
A12: ='Raw ratings'!A12 -> T11 | B12: C1 | C12: ='Raw ratings'!B12 -> LDA | D12: ='Raw ratings'!N12 -> 1 | E12: ='Raw ratings'!O12 -> 1 | F12: ='Raw ratings'!P12 -> 1 | G12: =COUNTIF($D$2:$D$61,"<"&D12)+(COUNTIF($D$2:$D$61,"="&D12)+1)/2 -> 5 | H12: =COUNTIF($E$2:$E$61,"<"&E12)+(COUNTIF($E$2:$E$61,"="&E12)+1)/2 -> 13.5 | I12: =COUNTIF($F$2:$F$61,"<"&F12)+(COUNTIF($F$2:$F$61,"="&F12)+1)/2 -> 2.5 | K12: Variance (tie-corr.) | L12: =(L2*L3/12)*((L4+1)-L11/(L4*(L4-1))) -> 3792.5847 | M12: =(M2*M3/12)*((M4+1)-M11/(M4*(M4-1))) -> 3976.2712 | N12: =(N2*N3/12)*((N4+1)-N11/(N4*(N4-1))) -> 3555.7627
A13: ='Raw ratings'!A13 -> T12 | B13: C1 | C13: ='Raw ratings'!B13 -> NMF | D13: ='Raw ratings'!N13 -> 3 | E13: ='Raw ratings'!O13 -> 3 | F13: ='Raw ratings'!P13 -> 3 | G13: =COUNTIF($D$2:$D$61,"<"&D13)+(COUNTIF($D$2:$D$61,"="&D13)+1)/2 -> 50 | H13: =COUNTIF($E$2:$E$61,"<"&E13)+(COUNTIF($E$2:$E$61,"="&E13)+1)/2 -> 53.5 | I13: =COUNTIF($F$2:$F$61,"<"&F13)+(COUNTIF($F$2:$F$61,"="&F13)+1)/2 -> 44 | K13: z (cont.-corr.) | L13: =(L6-L7-0.5)/SQRT(L12) -> 3.4749305 | M13: =(M6-M7-0.5)/SQRT(M12) -> 3.7981098 | N13: =(N6-N7-0.5)/SQRT(N12) -> 3.4965494
A14: ='Raw ratings'!A14 -> T13 | B14: C1 | C14: ='Raw ratings'!B14 -> NMF | D14: ='Raw ratings'!N14 -> 1 | E14: ='Raw ratings'!O14 -> 1 | F14: ='Raw ratings'!P14 -> 2 | G14: =COUNTIF($D$2:$D$61,"<"&D14)+(COUNTIF($D$2:$D$61,"="&D14)+1)/2 -> 5 | H14: =COUNTIF($E$2:$E$61,"<"&E14)+(COUNTIF($E$2:$E$61,"="&E14)+1)/2 -> 13.5 | I14: =COUNTIF($F$2:$F$61,"<"&F14)+(COUNTIF($F$2:$F$61,"="&F14)+1)/2 -> 16 | K14: p (one-sided) | L14: =1-NORMSDIST(L13) -> 0.00025549283 | M14: =1-NORMSDIST(M13) -> 7.2901858e-05 | N14: =1-NORMSDIST(N13) -> 0.00023565857
A15: ='Raw ratings'!A15 -> T14 | B15: C1 | C15: ='Raw ratings'!B15 -> NMF | D15: ='Raw ratings'!N15 -> 1 | E15: ='Raw ratings'!O15 -> 1 | F15: ='Raw ratings'!P15 -> 3 | G15: =COUNTIF($D$2:$D$61,"<"&D15)+(COUNTIF($D$2:$D$61,"="&D15)+1)/2 -> 5 | H15: =COUNTIF($E$2:$E$61,"<"&E15)+(COUNTIF($E$2:$E$61,"="&E15)+1)/2 -> 13.5 | I15: =COUNTIF($F$2:$F$61,"<"&F15)+(COUNTIF($F$2:$F$61,"="&F15)+1)/2 -> 44 | K15: LDA mean | L15: =AVERAGEIF($C$2:$C$61,"LDA",$D$2:$D$61) -> 1.9 | M15: =AVERAGEIF($C$2:$C$61,"LDA",$E$2:$E$61) -> 1.4 | N15: =AVERAGEIF($C$2:$C$61,"LDA",$F$2:$F$61) -> 2.2
A16: ='Raw ratings'!A16 -> T15 | B16: C1 | C16: ='Raw ratings'!B16 -> NMF | D16: ='Raw ratings'!N16 -> 2 | E16: ='Raw ratings'!O16 -> 1 | F16: ='Raw ratings'!P16 -> 2 | G16: =COUNTIF($D$2:$D$61,"<"&D16)+(COUNTIF($D$2:$D$61,"="&D16)+1)/2 -> 24.5 | H16: =COUNTIF($E$2:$E$61,"<"&E16)+(COUNTIF($E$2:$E$61,"="&E16)+1)/2 -> 13.5 | I16: =COUNTIF($F$2:$F$61,"<"&F16)+(COUNTIF($F$2:$F$61,"="&F16)+1)/2 -> 16 | K16: NMF mean | L16: =AVERAGEIF($C$2:$C$61,"NMF",$D$2:$D$61) -> 2.5 | M16: =AVERAGEIF($C$2:$C$61,"NMF",$E$2:$E$61) -> 2.2 | N16: =AVERAGEIF($C$2:$C$61,"NMF",$F$2:$F$61) -> 2.7666667
A17: ='Raw ratings'!A17 -> T16 | B17: C1 | C17: ='Raw ratings'!B17 -> NMF | D17: ='Raw ratings'!N17 -> 2 | E17: ='Raw ratings'!O17 -> 3 | F17: ='Raw ratings'!P17 -> 2 | G17: =COUNTIF($D$2:$D$61,"<"&D17)+(COUNTIF($D$2:$D$61,"="&D17)+1)/2 -> 24.5 | H17: =COUNTIF($E$2:$E$61,"<"&E17)+(COUNTIF($E$2:$E$61,"="&E17)+1)/2 -> 53.5 | I17: =COUNTIF($F$2:$F$61,"<"&F17)+(COUNTIF($F$2:$F$61,"="&F17)+1)/2 -> 16
A18: ='Raw ratings'!A18 -> T17 | B18: C1 | C18: ='Raw ratings'!B18 -> LDA | D18: ='Raw ratings'!N18 -> 1 | E18: ='Raw ratings'!O18 -> 1 | F18: ='Raw ratings'!P18 -> 2 | G18: =COUNTIF($D$2:$D$61,"<"&D18)+(COUNTIF($D$2:$D$61,"="&D18)+1)/2 -> 5 | H18: =COUNTIF($E$2:$E$61,"<"&E18)+(COUNTIF($E$2:$E$61,"="&E18)+1)/2 -> 13.5 | I18: =COUNTIF($F$2:$F$61,"<"&F18)+(COUNTIF($F$2:$F$61,"="&F18)+1)/2 -> 16
A19: ='Raw ratings'!A19 -> T18 | B19: C1 | C19: ='Raw ratings'!B19 -> LDA | D19: ='Raw ratings'!N19 -> 2 | E19: ='Raw ratings'!O19 -> 2 | F19: ='Raw ratings'!P19 -> 2 | G19: =COUNTIF($D$2:$D$61,"<"&D19)+(COUNTIF($D$2:$D$61,"="&D19)+1)/2 -> 24.5 | H19: =COUNTIF($E$2:$E$61,"<"&E19)+(COUNTIF($E$2:$E$61,"="&E19)+1)/2 -> 36.5 | I19: =COUNTIF($F$2:$F$61,"<"&F19)+(COUNTIF($F$2:$F$61,"="&F19)+1)/2 -> 16
A20: ='Raw ratings'!A20 -> T19 | B20: C1 | C20: ='Raw ratings'!B20 -> NMF | D20: ='Raw ratings'!N20 -> 3 | E20: ='Raw ratings'!O20 -> 3 | F20: ='Raw ratings'!P20 -> 3 | G20: =COUNTIF($D$2:$D$61,"<"&D20)+(COUNTIF($D$2:$D$61,"="&D20)+1)/2 -> 50 | H20: =COUNTIF($E$2:$E$61,"<"&E20)+(COUNTIF($E$2:$E$61,"="&E20)+1)/2 -> 53.5 | I20: =COUNTIF($F$2:$F$61,"<"&F20)+(COUNTIF($F$2:$F$61,"="&F20)+1)/2 -> 44
A21: ='Raw ratings'!A21 -> T20 | B21: C1 | C21: ='Raw ratings'!B21 -> LDA | D21: ='Raw ratings'!N21 -> 2 | E21: ='Raw ratings'!O21 -> 1 | F21: ='Raw ratings'!P21 -> 2 | G21: =COUNTIF($D$2:$D$61,"<"&D21)+(COUNTIF($D$2:$D$61,"="&D21)+1)/2 -> 24.5 | H21: =COUNTIF($E$2:$E$61,"<"&E21)+(COUNTIF($E$2:$E$61,"="&E21)+1)/2 -> 13.5 | I21: =COUNTIF($F$2:$F$61,"<"&F21)+(COUNTIF($F$2:$F$61,"="&F21)+1)/2 -> 16
A22: ='Raw ratings'!A22 -> T21 | B22: C1 | C22: ='Raw ratings'!B22 -> NMF | D22: ='Raw ratings'!N22 -> 2 | E22: ='Raw ratings'!O22 -> 3 | F22: ='Raw ratings'!P22 -> 3 | G22: =COUNTIF($D$2:$D$61,"<"&D22)+(COUNTIF($D$2:$D$61,"="&D22)+1)/2 -> 24.5 | H22: =COUNTIF($E$2:$E$61,"<"&E22)+(COUNTIF($E$2:$E$61,"="&E22)+1)/2 -> 53.5 | I22: =COUNTIF($F$2:$F$61,"<"&F22)+(COUNTIF($F$2:$F$61,"="&F22)+1)/2 -> 44
A23: ='Raw ratings'!A23 -> T22 | B23: C1 | C23: ='Raw ratings'!B23 -> NMF | D23: ='Raw ratings'!N23 -> 2 | E23: ='Raw ratings'!O23 -> 2 | F23: ='Raw ratings'!P23 -> 2 | G23: =COUNTIF($D$2:$D$61,"<"&D23)+(COUNTIF($D$2:$D$61,"="&D23)+1)/2 -> 24.5 | H23: =COUNTIF($E$2:$E$61,"<"&E23)+(COUNTIF($E$2:$E$61,"="&E23)+1)/2 -> 36.5 | I23: =COUNTIF($F$2:$F$61,"<"&F23)+(COUNTIF($F$2:$F$61,"="&F23)+1)/2 -> 16
A24: ='Raw ratings'!A24 -> T23 | B24: C1 | C24: ='Raw ratings'!B24 -> LDA | D24: ='Raw ratings'!N24 -> 2 | E24: ='Raw ratings'!O24 -> 1 | F24: ='Raw ratings'!P24 -> 2 | G24: =COUNTIF($D$2:$D$61,"<"&D24)+(COUNTIF($D$2:$D$61,"="&D24)+1)/2 -> 24.5 | H24: =COUNTIF($E$2:$E$61,"<"&E24)+(COUNTIF($E$2:$E$61,"="&E24)+1)/2 -> 13.5 | I24: =COUNTIF($F$2:$F$61,"<"&F24)+(COUNTIF($F$2:$F$61,"="&F24)+1)/2 -> 16
A25: ='Raw ratings'!A25 -> T24 | B25: C1 | C25: ='Raw ratings'!B25 -> NMF | D25: ='Raw ratings'!N25 -> 2 | E25: ='Raw ratings'!O25 -> 2 | F25: ='Raw ratings'!P25 -> 2 | G25: =COUNTIF($D$2:$D$61,"<"&D25)+(COUNTIF($D$2:$D$61,"="&D25)+1)/2 -> 24.5 | H25: =COUNTIF($E$2:$E$61,"<"&E25)+(COUNTIF($E$2:$E$61,"="&E25)+1)/2 -> 36.5 | I25: =COUNTIF($F$2:$F$61,"<"&F25)+(COUNTIF($F$2:$F$61,"="&F25)+1)/2 -> 16
A26: ='Raw ratings'!A26 -> T25 | B26: C1 | C26: ='Raw ratings'!B26 -> LDA | D26: ='Raw ratings'!N26 -> 2 | E26: ='Raw ratings'!O26 -> 1 | F26: ='Raw ratings'!P26 -> 2 | G26: =COUNTIF($D$2:$D$61,"<"&D26)+(COUNTIF($D$2:$D$61,"="&D26)+1)/2 -> 24.5 | H26: =COUNTIF($E$2:$E$61,"<"&E26)+(COUNTIF($E$2:$E$61,"="&E26)+1)/2 -> 13.5 | I26: =COUNTIF($F$2:$F$61,"<"&F26)+(COUNTIF($F$2:$F$61,"="&F26)+1)/2 -> 16
A27: ='Raw ratings'!A27 -> T26 | B27: C1 | C27: ='Raw ratings'!B27 -> LDA | D27: ='Raw ratings'!N27 -> 2 | E27: ='Raw ratings'!O27 -> 1 | F27: ='Raw ratings'!P27 -> 2 | G27: =COUNTIF($D$2:$D$61,"<"&D27)+(COUNTIF($D$2:$D$61,"="&D27)+1)/2 -> 24.5 | H27: =COUNTIF($E$2:$E$61,"<"&E27)+(COUNTIF($E$2:$E$61,"="&E27)+1)/2 -> 13.5 | I27: =COUNTIF($F$2:$F$61,"<"&F27)+(COUNTIF($F$2:$F$61,"="&F27)+1)/2 -> 16
A28: ='Raw ratings'!A28 -> T27 | B28: C1 | C28: ='Raw ratings'!B28 -> NMF | D28: ='Raw ratings'!N28 -> 3 | E28: ='Raw ratings'!O28 -> 3 | F28: ='Raw ratings'!P28 -> 3 | G28: =COUNTIF($D$2:$D$61,"<"&D28)+(COUNTIF($D$2:$D$61,"="&D28)+1)/2 -> 50 | H28: =COUNTIF($E$2:$E$61,"<"&E28)+(COUNTIF($E$2:$E$61,"="&E28)+1)/2 -> 53.5 | I28: =COUNTIF($F$2:$F$61,"<"&F28)+(COUNTIF($F$2:$F$61,"="&F28)+1)/2 -> 44
... A31: ='Raw ratings'!A31 -> T30 | B31: C1 | C31: ='Raw ratings'!B31 -> NMF | D31: ='Raw ratings'!N31 -> 3 | E31: ='Raw ratings'!O31 -> 3 | F31: ='Raw ratings'!P31 -> 3 | G31: =COUNTIF($D$2:$D$61,"<"&D31)+(COUNTIF($D$2:$D$61,"="&D31)+1)/2 -> 50 | H31: =COUNTIF($E$2:$E$61,"<"&E31)+(COUNTIF($E$2:$E$61,"="&E31)+1)/2 -> 53.5 | I31: =COUNTIF($F$2:$F$61,"<"&F31)+(COUNTIF($F$2:$F$61,"="&F31)+1)/2 -> 44
A32: ='Raw ratings'!A2 -> T01 | B32: C2 | C32: ='Raw ratings'!B2 -> NMF | D32: ='Raw ratings'!Q2 -> 3 | E32: ='Raw ratings'!R2 -> 2 | F32: ='Raw ratings'!S2 -> 3 | G32: =COUNTIF($D$2:$D$61,"<"&D32)+(COUNTIF($D$2:$D$61,"="&D32)+1)/2 -> 50 | H32: =COUNTIF($E$2:$E$61,"<"&E32)+(COUNTIF($E$2:$E$61,"="&E32)+1)/2 -> 36.5 | I32: =COUNTIF($F$2:$F$61,"<"&F32)+(COUNTIF($F$2:$F$61,"="&F32)+1)/2 -> 44
A33: ='Raw ratings'!A3 -> T02 | B33: C2 | C33: ='Raw ratings'!B3 -> LDA | D33: ='Raw ratings'!Q3 -> 1 | E33: ='Raw ratings'!R3 -> 1 | F33: ='Raw ratings'!S3 -> 1 | G33: =COUNTIF($D$2:$D$61,"<"&D33)+(COUNTIF($D$2:$D$61,"="&D33)+1)/2 -> 5 | H33: =COUNTIF($E$2:$E$61,"<"&E33)+(COUNTIF($E$2:$E$61,"="&E33)+1)/2 -> 13.5 | I33: =COUNTIF($F$2:$F$61,"<"&F33)+(COUNTIF($F$2:$F$61,"="&F33)+1)/2 -> 2.5
A34: ='Raw ratings'!A4 -> T03 | B34: C2 | C34: ='Raw ratings'!B4 -> LDA | D34: ='Raw ratings'!Q4 -> 2 | E34: ='Raw ratings'!R4 -> 1 | F34: ='Raw ratings'!S4 -> 2 | G34: =COUNTIF($D$2:$D$61,"<"&D34)+(COUNTIF($D$2:$D$61,"="&D34)+1)/2 -> 24.5 | H34: =COUNTIF($E$2:$E$61,"<"&E34)+(COUNTIF($E$2:$E$61,"="&E34)+1)/2 -> 13.5 | I34: =COUNTIF($F$2:$F$61,"<"&F34)+(COUNTIF($F$2:$F$61,"="&F34)+1)/2 -> 16
A35: ='Raw ratings'!A5 -> T04 | B35: C2 | C35: ='Raw ratings'!B5 -> NMF | D35: ='Raw ratings'!Q5 -> 3 | E35: ='Raw ratings'!R5 -> 3 | F35: ='Raw ratings'!S5 -> 3 | G35: =COUNTIF($D$2:$D$61,"<"&D35)+(COUNTIF($D$2:$D$61,"="&D35)+1)/2 -> 50 | H35: =COUNTIF($E$2:$E$61,"<"&E35)+(COUNTIF($E$2:$E$61,"="&E35)+1)/2 -> 53.5 | I35: =COUNTIF($F$2:$F$61,"<"&F35)+(COUNTIF($F$2:$F$61,"="&F35)+1)/2 -> 44
A36: ='Raw ratings'!A6 -> T05 | B36: C2 | C36: ='Raw ratings'!B6 -> NMF | D36: ='Raw ratings'!Q6 -> 3 | E36: ='Raw ratings'!R6 -> 2 | F36: ='Raw ratings'!S6 -> 3 | G36: =COUNTIF($D$2:$D$61,"<"&D36)+(COUNTIF($D$2:$D$61,"="&D36)+1)/2 -> 50 | H36: =COUNTIF($E$2:$E$61,"<"&E36)+(COUNTIF($E$2:$E$61,"="&E36)+1)/2 -> 36.5 | I36: =COUNTIF($F$2:$F$61,"<"&F36)+(COUNTIF($F$2:$F$61,"="&F36)+1)/2 -> 44
A37: ='Raw ratings'!A7 -> T06 | B37: C2 | C37: ='Raw ratings'!B7 -> LDA | D37: ='Raw ratings'!Q7 -> 1 | E37: ='Raw ratings'!R7 -> 1 | F37: ='Raw ratings'!S7 -> 1 | G37: =COUNTIF($D$2:$D$61,"<"&D37)+(COUNTIF($D$2:$D$61,"="&D37)+1)/2 -> 5 | H37: =COUNTIF($E$2:$E$61,"<"&E37)+(COUNTIF($E$2:$E$61,"="&E37)+1)/2 -> 13.5 | I37: =COUNTIF($F$2:$F$61,"<"&F37)+(COUNTIF($F$2:$F$61,"="&F37)+1)/2 -> 2.5
A38: ='Raw ratings'!A8 -> T07 | B38: C2 | C38: ='Raw ratings'!B8 -> LDA | D38: ='Raw ratings'!Q8 -> 2 | E38: ='Raw ratings'!R8 -> 1 | F38: ='Raw ratings'!S8 -> 3 | G38: =COUNTIF($D$2:$D$61,"<"&D38)+(COUNTIF($D$2:$D$61,"="&D38)+1)/2 -> 24.5 | H38: =COUNTIF($E$2:$E$61,"<"&E38)+(COUNTIF($E$2:$E$61,"="&E38)+1)/2 -> 13.5 | I38: =COUNTIF($F$2:$F$61,"<"&F38)+(COUNTIF($F$2:$F$61,"="&F38)+1)/2 -> 44
A39: ='Raw ratings'!A9 -> T08 | B39: C2 | C39: ='Raw ratings'!B9 -> LDA | D39: ='Raw ratings'!Q9 -> 3 | E39: ='Raw ratings'!R9 -> 2 | F39: ='Raw ratings'!S9 -> 3 | G39: =COUNTIF($D$2:$D$61,"<"&D39)+(COUNTIF($D$2:$D$61,"="&D39)+1)/2 -> 50 | H39: =COUNTIF($E$2:$E$61,"<"&E39)+(COUNTIF($E$2:$E$61,"="&E39)+1)/2 -> 36.5 | I39: =COUNTIF($F$2:$F$61,"<"&F39)+(COUNTIF($F$2:$F$61,"="&F39)+1)/2 -> 44
A40: ='Raw ratings'!A10 -> T09 | B40: C2 | C40: ='Raw ratings'!B10 -> LDA | D40: ='Raw ratings'!Q10 -> 2 | E40: ='Raw ratings'!R10 -> 1 | F40: ='Raw ratings'!S10 -> 3 | G40: =COUNTIF($D$2:$D$61,"<"&D40)+(COUNTIF($D$2:$D$61,"="&D40)+1)/2 -> 24.5 | H40: =COUNTIF($E$2:$E$61,"<"&E40)+(COUNTIF($E$2:$E$61,"="&E40)+1)/2 -> 13.5 | I40: =COUNTIF($F$2:$F$61,"<"&F40)+(COUNTIF($F$2:$F$61,"="&F40)+1)/2 -> 44
A41: ='Raw ratings'!A11 -> T10 | B41: C2 | C41: ='Raw ratings'!B11 -> NMF | D41: ='Raw ratings'!Q11 -> 2 | E41: ='Raw ratings'!R11 -> 2 | F41: ='Raw ratings'!S11 -> 3 | G41: =COUNTIF($D$2:$D$61,"<"&D41)+(COUNTIF($D$2:$D$61,"="&D41)+1)/2 -> 24.5 | H41: =COUNTIF($E$2:$E$61,"<"&E41)+(COUNTIF($E$2:$E$61,"="&E41)+1)/2 -> 36.5 | I41: =COUNTIF($F$2:$F$61,"<"&F41)+(COUNTIF($F$2:$F$61,"="&F41)+1)/2 -> 44
A42: ='Raw ratings'!A12 -> T11 | B42: C2 | C42: ='Raw ratings'!B12 -> LDA | D42: ='Raw ratings'!Q12 -> 2 | E42: ='Raw ratings'!R12 -> 1 | F42: ='Raw ratings'!S12 -> 2 | G42: =COUNTIF($D$2:$D$61,"<"&D42)+(COUNTIF($D$2:$D$61,"="&D42)+1)/2 -> 24.5 | H42: =COUNTIF($E$2:$E$61,"<"&E42)+(COUNTIF($E$2:$E$61,"="&E42)+1)/2 -> 13.5 | I42: =COUNTIF($F$2:$F$61,"<"&F42)+(COUNTIF($F$2:$F$61,"="&F42)+1)/2 -> 16
...

Sheet C_Domain_concordance
A1: Main coder (C1): confusion — Gold (model) rows × Predicted (coder) columns
A2: Gold \ Pred | B2: A | C2: B | D2: C | E2: D | F2: Inductive | G2: Support
A3: A | B3: =COUNTIFS('Raw ratings'!$E$2:$E$31,"A",'Raw ratings'!$G$2:$G$31,"A") -> 0 | C3: =COUNTIFS('Raw ratings'!$E$2:$E$31,"A",'Raw ratings'!$G$2:$G$31,"B") -> 5 | D3: =COUNTIFS('Raw ratings'!$E$2:$E$31,"A",'Raw ratings'!$G$2:$G$31,"C") -> 0 | E3: =COUNTIFS('Raw ratings'!$E$2:$E$31,"A",'Raw ratings'!$G$2:$G$31,"D") -> 0 | F3: =COUNTIFS('Raw ratings'!$E$2:$E$31,"A",'Raw ratings'!$G$2:$G$31,"Inductive") -> 1 | G3: =SUM(B3:F3) -> 6
A4: B | B4: =COUNTIFS('Raw ratings'!$E$2:$E$31,"B",'Raw ratings'!$G$2:$G$31,"A") -> 0 | C4: =COUNTIFS('Raw ratings'!$E$2:$E$31,"B",'Raw ratings'!$G$2:$G$31,"B") -> 11 | D4: =COUNTIFS('Raw ratings'!$E$2:$E$31,"B",'Raw ratings'!$G$2:$G$31,"C") -> 0 | E4: =COUNTIFS('Raw ratings'!$E$2:$E$31,"B",'Raw ratings'!$G$2:$G$31,"D") -> 0 | F4: =COUNTIFS('Raw ratings'!$E$2:$E$31,"B",'Raw ratings'!$G$2:$G$31,"Inductive") -> 2 | G4: =SUM(B4:F4) -> 13
A5: C | B5: =COUNTIFS('Raw ratings'!$E$2:$E$31,"C",'Raw ratings'!$G$2:$G$31,"A") -> 0 | C5: =COUNTIFS('Raw ratings'!$E$2:$E$31,"C",'Raw ratings'!$G$2:$G$31,"B") -> 0 | D5: =COUNTIFS('Raw ratings'!$E$2:$E$31,"C",'Raw ratings'!$G$2:$G$31,"C") -> 0 | E5: =COUNTIFS('Raw ratings'!$E$2:$E$31,"C",'Raw ratings'!$G$2:$G$31,"D") -> 0 | F5: =COUNTIFS('Raw ratings'!$E$2:$E$31,"C",'Raw ratings'!$G$2:$G$31,"Inductive") -> 0 | G5: =SUM(B5:F5) -> 0
A6: D | B6: =COUNTIFS('Raw ratings'!$E$2:$E$31,"D",'Raw ratings'!$G$2:$G$31,"A") -> 1 | C6: =COUNTIFS('Raw ratings'!$E$2:$E$31,"D",'Raw ratings'!$G$2:$G$31,"B") -> 0 | D6: =COUNTIFS('Raw ratings'!$E$2:$E$31,"D",'Raw ratings'!$G$2:$G$31,"C") -> 0 | E6: =COUNTIFS('Raw ratings'!$E$2:$E$31,"D",'Raw ratings'!$G$2:$G$31,"D") -> 0 | F6: =COUNTIFS('Raw ratings'!$E$2:$E$31,"D",'Raw ratings'!$G$2:$G$31,"Inductive") -> 2 | G6: =SUM(B6:F6) -> 3
A7: Inductive | B7: =COUNTIFS('Raw ratings'!$E$2:$E$31,"Inductive",'Raw ratings'!$G$2:$G$31,"A") -> 0 | C7: =COUNTIFS('Raw ratings'!$E$2:$E$31,"Inductive",'Raw ratings'!$G$2:$G$31,"B") -> 3 | D7: =COUNTIFS('Raw ratings'!$E$2:$E$31,"Inductive",'Raw ratings'!$G$2:$G$31,"C") -> 0 | E7: =COUNTIFS('Raw ratings'!$E$2:$E$31,"Inductive",'Raw ratings'!$G$2:$G$31,"D") -> 0 | F7: =COUNTIFS('Raw ratings'!$E$2:$E$31,"Inductive",'Raw ratings'!$G$2:$G$31,"Inductive") -> 5 | G7: =SUM(B7:F7) -> 8
A8: Pred count | B8: =SUM(B3:B7) -> 1 | C8: =SUM(C3:C7) -> 19 | D8: =SUM(D3:D7) -> 0 | E8: =SUM(E3:E7) -> 0 | F8: =SUM(F3:F7) -> 10 | G8: =SUM(B8:F8) -> 30
A10: Class | B10: Precision | C10: Recall | D10: F1 | E10: In union
A11: A | B11: =IFERROR(B3/B8,0) -> 0 | C11: =IFERROR(B3/G3,0) -> 0 | D11: =IFERROR(2*B11*C11/(B11+C11),0) -> 0 | E11: =IF(OR(G3>0,B8>0),1,0) -> 1
A12: B | B12: =IFERROR(C4/C8,0) -> 0.57894737 | C12: =IFERROR(C4/G4,0) -> 0.84615385 | D12: =IFERROR(2*B12*C12/(B12+C12),0) -> 0.6875 | E12: =IF(OR(G4>0,C8>0),1,0) -> 1
A13: C | B13: =IFERROR(D5/D8,0) -> 0 | C13: =IFERROR(D5/G5,0) -> 0 | D13: =IFERROR(2*B13*C13/(B13+C13),0) -> 0 | E13: =IF(OR(G5>0,D8>0),1,0) -> 0
A14: D | B14: =IFERROR(E6/E8,0) -> 0 | C14: =IFERROR(E6/G6,0) -> 0 | D14: =IFERROR(2*B14*C14/(B14+C14),0) -> 0 | E14: =IF(OR(G6>0,E8>0),1,0) -> 1
A15: Inductive | B15: =IFERROR(F7/F8,0) -> 0.5 | C15: =IFERROR(F7/G7,0) -> 0.625 | D15: =IFERROR(2*B15*C15/(B15+C15),0) -> 0.55555556 | E15: =IF(OR(G7>0,F8>0),1,0) -> 1
A17: Accuracy (overall) | B17: =(B3+C4+D5+E6+F7)/30 -> 0.53333333
A18: Macro-F1 (union labels) | B18: =SUMPRODUCT(D11:D15,E11:E15)/SUM(E11:E15) -> 0.31076389
A19: Accuracy — LDA topics | B19: =SUMIFS('Raw ratings'!$T$2:$T$31,'Raw ratings'!$B$2:$B$31,"LDA")/COUNTIF('Raw ratings'!$B$2:$B$31,"LDA") -> 0.6
A20: Accuracy — NMF topics | B20: =SUMIFS('Raw ratings'!$T$2:$T$31,'Raw ratings'!$B$2:$B$31,"NMF")/COUNTIF('Raw ratings'!$B$2:$B$31,"NMF") -> 0.46666667
A22: Secondary coder (C2): confusion — Gold (model) rows × Predicted (coder) columns
A23: Gold \ Pred | B23: A | C23: B | D23: C | E23: D | F23: Inductive | G23: Support
A24: A | B24: =COUNTIFS('Raw ratings'!$E$2:$E$31,"A",'Raw ratings'!$K$2:$K$31,"A") -> 0 | C24: =COUNTIFS('Raw ratings'!$E$2:$E$31,"A",'Raw ratings'!$K$2:$K$31,"B") -> 4 | D24: =COUNTIFS('Raw ratings'!$E$2:$E$31,"A",'Raw ratings'!$K$2:$K$31,"C") -> 1 | E24: =COUNTIFS('Raw ratings'!$E$2:$E$31,"A",'Raw ratings'!$K$2:$K$31,"D") -> 1 | F24: =COUNTIFS('Raw ratings'!$E$2:$E$31,"A",'Raw ratings'!$K$2:$K$31,"Inductive") -> 0 | G24: =SUM(B24:F24) -> 6
A25: B | B25: =COUNTIFS('Raw ratings'!$E$2:$E$31,"B",'Raw ratings'!$K$2:$K$31,"A") -> 1 | C25: =COUNTIFS('Raw ratings'!$E$2:$E$31,"B",'Raw ratings'!$K$2:$K$31,"B") -> 9 | D25: =COUNTIFS('Raw ratings'!$E$2:$E$31,"B",'Raw ratings'!$K$2:$K$31,"C") -> 0 | E25: =COUNTIFS('Raw ratings'!$E$2:$E$31,"B",'Raw ratings'!$K$2:$K$31,"D") -> 3 | F25: =COUNTIFS('Raw ratings'!$E$2:$E$31,"B",'Raw ratings'!$K$2:$K$31,"Inductive") -> 0 | G25: =SUM(B25:F25) -> 13
A26: C | B26: =COUNTIFS('Raw ratings'!$E$2:$E$31,"C",'Raw ratings'!$K$2:$K$31,"A") -> 0 | C26: =COUNTIFS('Raw ratings'!$E$2:$E$31,"C",'Raw ratings'!$K$2:$K$31,"B") -> 0 | D26: =COUNTIFS('Raw ratings'!$E$2:$E$31,"C",'Raw ratings'!$K$2:$K$31,"C") -> 0 | E26: =COUNTIFS('Raw ratings'!$E$2:$E$31,"C",'Raw ratings'!$K$2:$K$31,"D") -> 0 | F26: =COUNTIFS('Raw ratings'!$E$2:$E$31,"C",'Raw ratings'!$K$2:$K$31,"Inductive") -> 0 | G26: =SUM(B26:F26) -> 0
A27: D | B27: =COUNTIFS('Raw ratings'!$E$2:$E$31,"D",'Raw ratings'!$K$2:$K$31,"A") -> 1 | C27: =COUNTIFS('Raw ratings'!$E$2:$E$31,"D",'Raw ratings'!$K$2:$K$31,"B") -> 0 | D27: =COUNTIFS('Raw ratings'!$E$2:$E$31,"D",'Raw ratings'!$K$2:$K$31,"C") -> 0 | E27: =COUNTIFS('Raw ratings'!$E$2:$E$31,"D",'Raw ratings'!$K$2:$K$31,"D") -> 2 | F27: =COUNTIFS('Raw ratings'!$E$2:$E$31,"D",'Raw ratings'!$K$2:$K$31,"Inductive") -> 0 | G27: =SUM(B27:F27) -> 3
A28: Inductive | B28: =COUNTIFS('Raw ratings'!$E$2:$E$31,"Inductive",'Raw ratings'!$K$2:$K$31,"A") -> 1 | C28: =COUNTIFS('Raw ratings'!$E$2:$E$31,"Inductive",'Raw ratings'!$K$2:$K$31,"B") -> 2 | D28: =COUNTIFS('Raw ratings'!$E$2:$E$31,"Inductive",'Raw ratings'!$K$2:$K$31,"C") -> 1 | E28: =COUNTIFS('Raw ratings'!$E$2:$E$31,"Inductive",'Raw ratings'!$K$2:$K$31,"D") -> 2 | F28: =COUNTIFS('Raw ratings'!$E$2:$E$31,"Inductive",'Raw ratings'!$K$2:$K$31,"Inductive") -> 2 | G28: =SUM(B28:F28) -> 8
A29: Pred count | B29: =SUM(B24:B28) -> 3 | C29: =SUM(C24:C28) -> 15 | D29: =SUM(D24:D28) -> 2 | E29: =SUM(E24:E28) -> 8 | F29: =SUM(F24:F28) -> 2 | G29: =SUM(B29:F29) -> 30
A31: Class | B31: Precision | C31: Recall | D31: F1 | E31: In union
A32: A | B32: =IFERROR(B24/B29,0) -> 0 | C32: =IFERROR(B24/G24,0) -> 0 | D32: =IFERROR(2*B32*C32/(B32+C32),0) -> 0 | E32: =IF(OR(G24>0,B29>0),1,0) -> 1
A33: B | B33: =IFERROR(C25/C29,0) -> 0.6 | C33: =IFERROR(C25/G25,0) -> 0.69230769 | D33: =IFERROR(2*B33*C33/(B33+C33),0) -> 0.64285714 | E33: =IF(OR(G25>0,C29>0),1,0) -> 1
A34: C | B34: =IFERROR(D26/D29,0) -> 0 | C34: =IFERROR(D26/G26,0) -> 0 | D34: =IFERROR(2*B34*C34/(B34+C34),0) -> 0 | E34: =IF(OR(G26>0,D29>0),1,0) -> 1
A35: D | B35: =IFERROR(E27/E29,0) -> 0.25 | C35: =IFERROR(E27/G27,0) -> 0.66666667 | D35: =IFERROR(2*B35*C35/(B35+C35),0) -> 0.36363636 | E35: =IF(OR(G27>0,E29>0),1,0) -> 1
A36: Inductive | B36: =IFERROR(F28/F29,0) -> 1 | C36: =IFERROR(F28/G28,0) -> 0.25 | D36: =IFERROR(2*B36*C36/(B36+C36),0) -> 0.4 | E36: =IF(OR(G28>0,F29>0),1,0) -> 1
A38: Accuracy (overall) | B38: =(B24+C25+D26+E27+F28)/30 -> 0.43333333
A39: Macro-F1 (union labels) | B39: =SUMPRODUCT(D32:D36,E32:E36)/SUM(E32:E36) -> 0.2812987
A40: Accuracy — LDA topics | B40: =SUMIFS('Raw ratings'!$U$2:$U$31,'Raw ratings'!$B$2:$B$31,"LDA")/COUNTIF('Raw ratings'!$B$2:$B$31,"LDA") -> 0.46666667
A41: Accuracy — NMF topics | B41: =SUMIFS('Raw ratings'!$U$2:$U$31,'Raw ratings'!$B$2:$B$31,"NMF")/COUNTIF('Raw ratings'!$B$2:$B$31,"NMF") -> 0.4
A43: C1–C2 domain agreement | B43: =SUM('Raw ratings'!$V$2:$V$31)/30 -> 0.53333333

Sheet Tables
A1: Tables. Human validation results (two coders, 30 no-RAKE topics)
A3: Table 5. Inter-coder reliability (Main vs Secondary)
A4: Criterion | B4: % agreement | C4: Cohen's kappa | D4: Band (Landis & Koch)
A5: Coherence | B5: ='A_Reliability(kappa)'!B11 -> 0.5 | C5: ='A_Reliability(kappa)'!B10 -> 0.20071048 | D5: =IF(C5<=0.2,"Slight",IF(C5<=0.4,"Fair",IF(C5<=0.6,"Moderate",IF(C5<=0.8,"Substantial","Almost perfect")))) -> Fair
A6: Domain | B6: ='A_Reliability(kappa)'!B25 -> 0.53333333 | C6: ='A_Reliability(kappa)'!B24 -> 0.29054054 | D6: =IF(C6<=0.2,"Slight",IF(C6<=0.4,"Fair",IF(C6<=0.6,"Moderate",IF(C6<=0.8,"Substantial","Almost perfect")))) -> Fair
A7: Label | B7: ='A_Reliability(kappa)'!B37 -> 0.6 | C7: ='A_Reliability(kappa)'!B36 -> 0.40594059 | D7: =IF(C7<=0.2,"Slight",IF(C7<=0.4,"Fair",IF(C7<=0.6,"Moderate",IF(C7<=0.8,"Substantial","Almost perfect")))) -> Moderate
A8: Fidelity | B8: ='A_Reliability(kappa)'!B49 -> 0.5 | C8: ='A_Reliability(kappa)'!B48 -> 0.21875 | D8: =IF(C8<=0.2,"Slight",IF(C8<=0.4,"Fair",IF(C8<=0.6,"Moderate",IF(C8<=0.8,"Substantial","Almost perfect")))) -> Fair
A11: Table 6. NMF vs LDA on human-rated quality (pooled; ratings 1–3; one-sided Mann–Whitney U)
A12: Criterion | B12: LDA mean | C12: NMF mean | D12: U | E12: p
A13: Coherence | B13: ='B_NMF_vs_LDA(MW)'!L15 -> 1.9 | C13: ='B_NMF_vs_LDA(MW)'!L16 -> 2.5 | D13: ='B_NMF_vs_LDA(MW)'!L6 -> 664.5 | E13: ='B_NMF_vs_LDA(MW)'!L14 -> 0.00025549283
A14: Label | B14: ='B_NMF_vs_LDA(MW)'!M15 -> 1.4 | C14: ='B_NMF_vs_LDA(MW)'!M16 -> 2.2 | D14: ='B_NMF_vs_LDA(MW)'!M6 -> 690 | E14: ='B_NMF_vs_LDA(MW)'!M14 -> 7.2901858e-05
A15: Fidelity | B15: ='B_NMF_vs_LDA(MW)'!N15 -> 2.2 | C15: ='B_NMF_vs_LDA(MW)'!N16 -> 2.7666667 | D15: ='B_NMF_vs_LDA(MW)'!N6 -> 659 | E15: ='B_NMF_vs_LDA(MW)'!N14 -> 0.00023565857
A18: Table 7. Concordance of each coder's independent domain judgment with the model's assignment
A19: Coder | B19: Overall acc. | C19: LDA acc. | D19: NMF acc. | E19: Macro-F1
A20: Main coder | B20: =C_Domain_concordance!B17 -> 0.53333333 | C20: =C_Domain_concordance!B19 -> 0.6 | D20: =C_Domain_concordance!B20 -> 0.46666667 | E20: =C_Domain_concordance!B18 -> 0.31076389
A21: Secondary coder | B21: =C_Domain_concordance!B38 -> 0.43333333 | C21: =C_Domain_concordance!B40 -> 0.46666667 | D21: =C_Domain_concordance!B41 -> 0.4 | E21: =C_Domain_concordance!B39 -> 0.2812987
A22: C1–C2 domain agreement | B22: =C_Domain_concordance!B43 -> 0.53333333
A24: All values are computed live from the 'Raw ratings' sheet via the A/B/C computation sheets.
